Workbook

Sheet Competencias y capacidades
A1: Áreas | B1: Competencia1 | C1: Competencia2 | D1: Competencia3 | E1: Competencia4 | G1: Area | H1: Competencia | I1: Capacidad1 | J1: Capacidad2 | K1: Capacidad3 | L1: Capacidad4 | M1: Capacidad5 | N1: Capacidad6
A2: ARTE Y CULTURA | B2: Aprecia de manera crítica manifestaciones artistico-culturales | C2: Crea proyectos desde los lenguajes artisticos | G2: DESARROLLO PERSONAL, CIUDADANÍA Y CÍVICA | H2: Construye su identidad | I2: Se valora a sí mismo | J2: Autorregula sus emociones | K2: Reflexiona y argumenta éticamente | L2: Vive su sexualidad de manera integral y responsable de acuerdo a su etapa de desarrollo y madurez.
A3: CASTELLANO COMO SEGUNDA LENGUA | B3: Se comunica oralmente en castellano como segunda lengua | C3: Lee diversos tipos de textos escritos en castellano como segunda lengua | D3: Escribe diversos tipos de textos en castellano como segunda lengua | H3: Convive y participa democráticamente en la búsqueda del bien común | I3: Interactúa con todas las personas | J3: Construye y asume acuerdos y normas | K3: Maneja conflictos de manera constructiva | L3: Delibera sobre asuntos públicos | M3: Participa en acciones que promueven el bienestar común
A4: CIENCIA Y TECNOLOGÍA | B4: Indaga mediante métodos cientificos para construir conocimientos | C4: Explica el mundo físico basándose en conocimientos sobre los seres vivos; materia y energía; biodiversidad, Tierra y universo | D4: Diseña y construye soluciones tecnológicas para resolver problemas de su entorno | G4: CIENCIAS SOCIALES | H4: Construye interpretaciones históricas | I4: Interpreta críticamente fuentes diversas | J4: Comprende el tiempo histórico | K4: Explica y argumenta procesos históricos
A5: CIENCIAS SOCIALES | B5: Construye interpretaciones históricas | C5: Gestiona responsablemente el espacio y el ambiente | D5: Gestiona responsablemente los recursos económicos | H5: Gestiona responsablemente el espacio y el ambiente | I5: Comprende las relaciones entre los elementos naturales y sociales | J5: Maneja fuentes de información para comprender el espacio geográfico y el ambiente | K5: Genera acciones para preservar el ambiente local y global
A6: COMUNICACIÓN | B6: Se comunica oralmente en su lengua materna | C6: Lee diversos tipos de textos escritos en su lengua materna | D6: Escribe diversos tipos de textos en lengua materna | H6: Gestiona responsablemente los recursos económicos | I6: Comprende las relaciones entre los elementos del sistema económico y financiero | J6: Toma decisiones económicas y financieras
A7: QUECHUA | B7: Se comunica oralmente en su lengua materna | C7: Lee diversos tipos de textos escritos en su lengua materna | D7: Escribe diversos tipos de textos en lengua materna | G7: EDUCACIÓN RELIGIOSA | H7: Construye su identidad como persona humana, amada por Dios, digna, libre y trascendente, comprendiendo la doctrina de su propia religión, abierto al diálogo con las que le son cercanas | I7: Conoce a Dios y asume su identidad religiosa como persona digna, libre y trascendente | J7: Cultiva y valora las manifestaciones religiosas de su entorno argumentando su fe de manera comprensible y respetuosa
A8: DESARROLLO PERSONAL, CIUDADANÍA Y CÍVICA | B8: Construye su identidad | C8: Convive y participa democráticamente en la búsqueda del bien común | H8: Asume la experiencia del encuentro personal y comunitario con Dios en su proyecto de vida en coherencia con su creencia religiosa | I8: Transforma su entorno desde el encuentro personal y comunitario con Dios y desde la fe que profesa | J8: Actúa coherentemente en razón de su fe según los principios de su conciencia moral en situaciones concretas de la vida.
A9: EDUCACIÓN FÍSICA | B9: Se desenvuelve de manera autónoma a través de su motricidad | C9: Asume una vida saludable | D9: Interactúa a través de sus habilidades sociomotrices | G9: EDUCACIÓN PARA EL TRABAJO | H9: Gestiona proyectos de emprendimiento económico o social | I9: Crea propuestas de valor | J9: Trabaja cooperativamente para lograr objetivos y metas | K9: Aplica habilidades técnicas | L9: Evalúa los resultados del proyecto de emprendimiento
A10: EDUCACIÓN PARA EL TRABAJO | B10: Gestiona proyectos de emprendimiento económico o social | G10: EDUCACIÓN FÍSICA | H10: Se desenvuelve de manera autónoma a través de su motricidad | I10: Comprende su cuerpo | J10: Se expresa corporalmente
A11: EDUCACIÓN RELIGIOSA | B11: Construye su identidad como persona humana, amada por Dios, digna, libre y trascendente, comprendiendo la doctrina de su propia religión, abierto al diálogo con las que le son cercanas | C11: Asume la experiencia del encuentro personal y comunitario con Dios en su proyecto de vida en coherencia con su creencia religiosa | H11: Asume una vida saludable | I11: Comprende las relaciones entre la actividad física, alimentación, postura e higiene y la salud | J11: Incorpora prácticas que mejoran su calidad de vida
A12: INGLÉS | B12: Se comunica oralmente en inglés como lengua extranjera | C12: Lee diversos tipos de textos escritos en inglés como lengua extranjera | D12: Escribe diversos tipos de textos en inglés como lengua extranjera | H12: Interactúa a través de sus habilidades sociomotrices | I12: Se relaciona utilizando sus habilidades sociomotrices | J12: Crea y aplica estrategias y tácticas de juego
A13: MATEMÁTICA | B13: Resuelve problemas de cantidad | C13: Resuelve problemas de regularidad, equivalencia y cambio | D13: Resuelve problemas de forma, movimiento y localización | E13: Resuelve problemas de gestión de datos e incertidumbre | G13: COMUNICACIÓN | H13: Se comunica oralmente en su lengua materna | I13: Obtiene información de textos orales | J13: Infiere e interpreta información de textos orales | K13: Adecua, organiza y desarrolla las ideas de forma coherente y cohesionada | L13: Utiliza recursos no verbales y paraverbales de forma estratégica | M13: Interactúa estratégicamente con distintos interlocutores | N13: Reflexiona y evalúa la forma, el contenido y el contexto del texto oral
H14: Lee diversos tipos de textos escritos en su lengua materna | I14: Obtiene información del texto escrito | J14: Infiere e interpreta información del texto | K14: Reflexiona y evalúa la forma, el contenido y el contexto del texto escrito
H15: Escribe diversos tipos de textos en lengua materna | I15: Adecúa el texto a la situación comunicativa | J15: Organiza y desarrolla las ideas de forma coherente y cohesionada | K15: Utiliza convenciones del lenguaje escrito de forma pertinente | L15: Reflexiona y evalúa la forma, el contenido y el contexto del texto escrito
G16: ARTE Y CULTURA | H16: Aprecia de manera crítica manifestaciones artistico-culturales | I16: Percibe manifestaciones artistico-culturales | J16: Contextualiza las manifestaciones artistico-culturales | K16: Reflexiona creativa y críticamente sobre las manifestaciones artistico- culturales
H17: Crea proyectos desde los lenguajes artisticos | I17: Explora y experimenta los lenguajes de las artes | J17: Aplica procesos de creación | K17: Evalúa y comunica sus procesos y proyectos
G18: CASTELLANO COMO SEGUNDA LENGUA | H18: Se comunica oralmente en castellano como segunda lengua | I18: Obtiene información de textos orales | J18: Infiere e interpreta información de textos orales | K18: Adecúa, organiza y desarrolla las ideas de forma coherente y cohesionada | L18: Utiliza recursos no verbales y paraverbales de forma estratégica | M18: Interactúa estratégicamente con distintos interlocutores | N18: Reflexiona y evalúa la forma, el contenido y el contexto del texto oral
H19: Lee diversos tipos de textos escritos en castellano como segunda lengua | I19: Obtiene información del texto escrito | J19: Infiere e interpreta información del texto | K19: Reflexiona y evalúa la forma, el contenido y el contexto del texto escrito
H20: Escribe diversos tipos de textos en castellano como segunda lengua | I20: Adecúa el texto a la situación comunicativa | J20: Organiza y desarrolla las ideas de forma coherente y cohesionada | K20: Utiliza convenciones del lenguaje escrito de forma pertinente | L20: Reflexiona y evalúa la forma, el contenido y el contexto del texto escrito
G21: INGLÉS | H21: Se comunica oralmente en inglés como lengua extranjera | I21: Obtiene información de textos orales | J21: Infiere e interpreta información de textos orales | K21: Adecua, organiza y desarrolla las ideas de forma coherente y cohesionada | L21: Utiliza recursos no verbales y paraverbales de forma estratégica | M21: Interactúa estratégicamente con distintos interlocutores | N21: Reflexiona y evalúa la forma, el contenido y el contexto del texto oral
H22: Lee diversos tipos de textos escritos en inglés como lengua extranjera | I22: Obtiene información del texto escrito | J22: Infiere e interpreta información del texto | K22: Reflexiona y evalúa la forma, el contenido y el contexto del texto escrito
H23: Escribe diversos tipos de textos en inglés como lengua extranjera | I23: Adecúa el texto a la situación comunicativa | J23: Organiza y desarrolla las ideas de forma coherente y cohesionada | K23: Utiliza convenciones del lenguaje escrito de forma pertinente | L23: Reflexiona y evalúa la forma, el contenido y el contexto del texto escrito
G24: MATEMÁTICA | H24: Resuelve problemas de cantidad | I24: Traduce cantidades a expresiones numéricas | J24: Comunica su comprensión sobre los números y las operaciones | K24: Usa estrategias y procedimientos de estimación y cálculo | L24: Argumenta afirmaciones sobre las relaciones numéricas y las operaciones
H25: Resuelve problemas de regularidad, equivalencia y cambio | I25: Traduce datos y condiciones a expresiones algebraicas | J25: Comunica su comprensión sobre las relaciones algebraicas | K25: Usa estrategias y procedimientos para encontrar reglas generales | L25: Argumenta afirmaciones sobre relaciones de cambio y equivalencia
H26: Resuelve problemas de forma, movimiento y localización | I26: Modela objetos con formas geométricas y sus transformaciones | J26: Comunica su comprensión sobre las formas y relaciones geométricas | K26: Usa estrategias y procedimientos para orientarse en el espacio | L26: Argumenta afirmaciones sobre relaciones geométricas
H27: Resuelve problemas de gestión de datos e incertidumbre | I27: Representa datos con gráficos y medidas estadísticas o probabilísticas | J27: Comunica la comprensión de los conceptos estadísticos y probabilísticos | K27: Usa estrategias y procedimientos para recopilar y procesar datos | L27: Sustenta conclusiones o decisiones basado en información obtenida
G28: CIENCIA Y TECNOLOGÍA | H28: Indaga mediante métodos cientificos para construir conocimientos | I28: Problematiza situaciones | J28: Diseña estrategias para hacer indagación | K28: Genera y registra datos e información | L28: Analiza datos e información | M28: Evalúa y comunica el proceso y los resultados de su indagación
H29: Explica el mundo físico basándose en conocimientos sobre los seres vivos; materia y energía; biodiversidad, Tierra y universo | I29: Comprende y usa conocimientos sobre los seres vivos; materia y energía; biodiversidad, Tierra y universo | J29: Evalúa las implicancias del saber y del quehacer cientifico y tecnológico
H30: Diseña y construye soluciones tecnológicas para resolver problemas de su entorno | I30: Determina una alternativa de solución tecnológica | J30: Diseña la alternativa de solución tecnológica | K30: Implementa y valida alternativas de solución tecnológica | L30: Evalúa y comunica el funcionamiento y los impactos de su alternativa de solución tecnológica
G31: QUECHUA | H31: Se comunica oralmente en su lengua materna | I31: Obtiene información de textos orales | J31: Infiere e interpreta información de textos orales | K31: Adecua, organiza y desarrolla las ideas de forma coherente y cohesionada | L31: Utiliza recursos no verbales y paraverbales de forma estratégica | M31: Interactúa estratégicamente con distintos interlocutores | N31: Reflexiona y evalúa la forma, el contenido y el contexto del texto oral
H32: Lee diversos tipos de textos escritos en su lengua materna | I32: Obtiene información del texto escrito | J32: Infiere e interpreta información del texto | K32: Reflexiona y evalúa la forma, el contenido y el contexto del texto escrito
H33: Escribe diversos tipos de textos en lengua materna | I33: Adecúa el texto a la situación comunicativa | J33: Organiza y desarrolla las ideas de forma coherente y cohesionada | K33: Utiliza convenciones del lenguaje escrito de forma pertinente | L33: Reflexiona y evalúa la forma, el contenido y el contexto del texto escrito
F36: 1ro
F37: 2do
F38: 3ro
F39: 4to
F40: 5to
F43: "A"
F44: "B"
...

Sheet Datos 
D2: GRADO
D3: 3ro
D4: SECCIÓN
D5: "A" | Y5: E | Z5: 5°
B7: N° | C7: DNI | D7: Apellidos y Nombres
B8: 1
B9: 2
B10: 3
B11: 4
B12: 5
B13: 6
B14: 7
B15: 8
B16: 9
B17: 10
B18: 11
B19: 12
... B45: 38

Sheet ARTE
C1: REGISTRO DE EVALUACIÓN NIVEL SECUNDARIA III BIMESTRE 2026
G3: DOCENTE: | V3: GRADO: | Y3: ='Datos '!D3 -> 3ro | AC3: CELULAR
G4: ÁREA: | K4: ARTE Y CULTURA | V4: SECCIÓN: | Y4: ='Datos '!D5 -> "A" | AC4: FECHA DE ENTREGA
A6: Nº DE ORDEN | B6: APELLIDOS Y NOMBRES | C6: CUARTO BIMESTRE | AD6: CALIFICACIÓN DEL ÁREA | AE6: III BIMESTRE
C7: COMPETENCIA 01 | K7: COMPETENCIA 02 | R7: COMPETENCIA 03 | X7: COMPETENCIA 04 | AE7: COMPETENCIAS TRANSVERSALES
C8: =IF(VLOOKUP(K4,'Competencias y capacidades'!A2:E13,2,FALSE())=0,"",VLOOKUP(K4,'Competencias y capacidades'!A2:E13,2,FALSE())) -> Aprecia de manera crítica manifestaciones artistico-culturales | J8: CONCLUSIÓN DESCRIPTIVA | K8: =IF(VLOOKUP(K4,'Competencias y capacidades'!A2:E13,3,FALSE())=0,"",VLOOKUP(K4,'Competencias y capacidades'!A2:E13,3,FALSE())) -> Crea proyectos desde los lenguajes artisticos | Q8: CONCLUSIÓN DESCRIPTIVA | R8: =IF(VLOOKUP(K4,'Competencias y capacidades'!A2:E13,4,FALSE())=0,"",VLOOKUP(K4,'Competencias y capacidades'!A2:E13,4,FALSE())) | W8: CONCLUSIÓN DESCRIPTIVA | X8: =IF(VLOOKUP(K4,'Competencias y capacidades'!A2:E13,5,FALSE())=0,"",VLOOKUP(K4,'Competencias y capacidades'!A2:E13,5,FALSE())) | AC8: CONCLUSIÓN DESCRIPTIVA | AE8: Se desenvuelve en entornos virtuales generados por las TIC | AJ8: Gestiona su aprendizaje de manera autónoma | AX8: COMPETENCIA 1 | BE8: COMPETENCIA 2 | BK8: COMPETENCIA 3 | BP8: COMPETENCIA 4 | BU8: PROMEDIO DEL AREA | BV8: COMPETENCIA TRASVERSAL 1 | CA8: COMPETENCIA TRASVERSAL 2
C9: =IF(IF($C$8="","",VLOOKUP($C$8,'Competencias y capacidades'!$H$2:$N$33,2,FALSE()))=0,"",IF($C$8="","",VLOOKUP($C$8,'Competencias y capacidades'!$H$2:$N$33,2,FALSE()))) -> Percibe manifestaciones artistico-culturales | D9: =IF(IF($C$8="","",VLOOKUP($C$8,'Competencias y capacidades'!$H$2:$N$33,3,FALSE()))=0,"",IF($C$8="","",VLOOKUP($C$8,'Competencias y capacidades'!$H$2:$N$33,3,FALSE()))) -> Contextualiza las manifestaciones artistico-culturales | E9: =IF(IF($C$8="","",VLOOKUP($C$8,'Competencias y capacidades'!$H$2:$N$33,4,FALSE()))=0,"",IF($C$8="","",VLOOKUP($C$8,'Competencias y capacidades'!$H$2:$N$33,4,FALSE()))) -> Reflexiona creativa y críticamente sobre las manifestaciones artistico- culturales | F9: =IF(IF($C$8="","",VLOOKUP($C$8,'Competencias y capacidades'!$H$2:$N$33,5,FALSE()))=0,"",IF($C$8="","",VLOOKUP($C$8,'Competencias y capacidades'!$H$2:$N$33,5,FALSE()))) | G9: =IF(IF($C$8="","",VLOOKUP($C$8,'Competencias y capacidades'!$H$2:$N$33,6,FALSE()))=0,"",IF($C$8="","",VLOOKUP($C$8,'Competencias y capacidades'!$H$2:$N$33,6,FALSE()))) | H9: =IF(IF($C$8="","",VLOOKUP($C$8,'Competencias y capacidades'!$H$2:$N$33,7,FALSE()))=0,"",IF($C$8="","",VLOOKUP($C$8,'Competencias y capacidades'!$H$2:$N$33,7,FALSE()))) | I9: NIVEL DE LOGRO | J9: CO1 | K9: =IF(IF($K$8="","",VLOOKUP($K$8,'Competencias y capacidades'!$H$2:$N$33,2,FALSE()))=0,"",IF($K$8="","",VLOOKUP($K$8,'Competencias y capacidades'!$H$2:$N$33,2,FALSE()))) -> Explora y experimenta los lenguajes de las artes | L9: =IF(IF($K$8="","",VLOOKUP($K$8,'Competencias y capacidades'!$H$2:$N$33,3,FALSE()))=0,"",IF($K$8="","",VLOOKUP($K$8,'Competencias y capacidades'!$H$2:$N$33,3,FALSE()))) -> Aplica procesos de creación | M9: =IF(IF($K$8="","",VLOOKUP($K$8,'Competencias y capacidades'!$H$2:$N$33,4,FALSE()))=0,"",IF($K$8="","",VLOOKUP($K$8,'Competencias y capacidades'!$H$2:$N$33,4,FALSE()))) -> Evalúa y comunica sus procesos y proyectos | N9: =IF(IF($K$8="","",VLOOKUP($K$8,'Competencias y capacidades'!$H$2:$N$33,5,FALSE()))=0,"",IF($K$8="","",VLOOKUP($K$8,'Competencias y capacidades'!$H$2:$N$33,5,FALSE()))) | O9: =IF(IF($K$8="","",VLOOKUP($K$8,'Competencias y capacidades'!$H$2:$N$33,6,FALSE()))=0,"",IF($K$8="","",VLOOKUP($K$8,'Competencias y capacidades'!$H$2:$N$33,6,FALSE()))) | P9: NIVEL DEL LOGRO | Q9: CO2 | R9: =IF(IF($R$8="","",VLOOKUP($R$8,'Competencias y capacidades'!$H$2:$N$33,2,FALSE()))=0,"",IF($R$8="","",VLOOKUP($R$8,'Competencias y capacidades'!$H$2:$N$33,2,FALSE()))) | S9: =IF(IF($R$8="","",VLOOKUP($R$8,'Competencias y capacidades'!$H$2:$N$33,3,FALSE()))=0,"",IF($R$8="","",VLOOKUP($R$8,'Competencias y capacidades'!$H$2:$N$33,3,FALSE()))) | T9: =IF(IF($R$8="","",VLOOKUP($R$8,'Competencias y capacidades'!$H$2:$N$33,4,FALSE()))=0,"",IF($R$8="","",VLOOKUP($R$8,'Competencias y capacidades'!$H$2:$N$33,4,FALSE()))) | U9: =IF(IF($R$8="","",VLOOKUP($R$8,'Competencias y capacidades'!$H$2:$N$33,5,FALSE()))=0,"",IF($R$8="","",VLOOKUP($R$8,'Competencias y capacidades'!$H$2:$N$33,5,FALSE()))) | V9: NIVEL DEL LOGRO | W9: CO3 | X9: =IF(IF($X$8="","",VLOOKUP($X$8,'Competencias y capacidades'!$H$2:$N$33,2,FALSE()))=0,"",IF($X$8="","",VLOOKUP($X$8,'Competencias y capacidades'!$H$2:$N$33,2,FALSE()))) | Y9: =IF(IF($X$8="","",VLOOKUP($X$8,'Competencias y capacidades'!$H$2:$N$33,3,FALSE()))=0,"",IF($X$8="","",VLOOKUP($X$8,'Competencias y capacidades'!$H$2:$N$33,3,FALSE()))) | Z9: =IF(IF($X$8="","",VLOOKUP($X$8,'Competencias y capacidades'!$H$2:$N$33,4,FALSE()))=0,"",IF($X$8="","",VLOOKUP($X$8,'Competencias y capacidades'!$H$2:$N$33,4,FALSE()))) | AA9: =IF(IF($X$8="","",VLOOKUP($X$8,'Competencias y capacidades'!$H$2:$N$33,5,FALSE()))=0,"",IF($X$8="","",VLOOKUP($X$8,'Competencias y capacidades'!$H$2:$N$33,5,FALSE()))) | AB9: NIVEL DEL LOGRO | AC9: CO4 | AE9: Personaliza entornos virtuales | AF9: Gestiona información del entorno virtual | AG9: Interactúa en entornos virtuales | AH9: Crea objetos virtuales en diversos formatos | AI9: VALORACIÓN | AJ9: Define metas de aprendizaje | AK9: Organiza acciones estratégicas para alcanzar sus metas de aprendizaje | AL9: Monitorea y ajusta su desempeño durante el proceso de aprendizaje | AM9: VALORACIÓN | AN9: CONCLUSIONES DESCRIPTIVAS DEL AREA | AX9: CAPACIDAD 1 | AY9: CAPACIDAD 2 | AZ9: CAPACIDAD 3 | BA9: CAPACIDAD4 | BB9: CAPACIDAD 5 | BC9: CAPACIDAD 6 | BD9: PROMEDIO | BE9: CAPACIDAD 1 | BF9: CAPACIDAD 2 | BG9: CAPACIDAD 3 | BH9: CAPACIDAD4 | BI9: CAPACIDAD 5 | BJ9: PROMEDIO | BK9: CAPACIDAD 1 | BL9: CAPACIDAD 2 | BM9: CAPACIDAD 3 | BN9: CAPACIDAD4 | BO9: PROMEDIO | BP9: CAPACIDAD 1 | BQ9: CAPACIDAD 2 | BR9: CAPACIDAD 3 | BS9: CAPACIDAD4 | BT9: PROMEDIO | BV9: CAPACIDAD 1 | BW9: CAPACIDAD 2 | BX9: CAPACIDAD 3 | BY9: CAPACIDAD4 | BZ9: PROMEDIO | CA9: CAPACIDAD 1 | CB9: CAPACIDAD 2 | CC9: CAPACIDAD 3 | CD9: PROMEDIO
A10: 1 | B10: ='Datos '!D8 -> 0 | I10: =IF(BD10="","",IF(BD10=3,"AD",IF(BD10=2, "A",IF(BD10= 1, "B",IF(BD10= 0, "C"))))) | P10: =IF(BJ10="","",IF(BJ10=3,"AD",IF(BJ10=2, "A",IF(BJ10= 1, "B",IF(BJ10= 0, "C"))))) | V10: =IF(BO10="","",IF(BO10=3,"AD",IF(BO10=2, "A",IF(BO10= 1, "B",IF(BO10= 0, "C"))))) | AB10: =IF(BT10="","",IF(BT10=3,"AD",IF(BT10=2, "A",IF(BT10= 1, "B",IF(BT10= 0, "C"))))) | AD10: =IF(BU10="","",IF(BU10=3,"AD",IF(BU10=2, "A",IF(BU10= 1, "B",IF(BU10= 0, "C"))))) | AI10: =IF(BZ10="","",IF(BZ10=3,"AD",IF(BZ10=2, "A",IF(BZ10= 1, "B",IF(BZ10= 0, "C"))))) | AM10: =IF(CD10="","",IF(CD10=3,"AD",IF(CD10=2, "A",IF(CD10= 1, "B",IF(CD10= 0, "C"))))) | AN10: =IF(AD10="","No presenta evidencias para su calificación",IF(AD10="AD","Demuestra aprendizaje que van más allá del nivel esperado",IF(AD10="A","Demuestra manejo satisfactorio en todas las tareas propuestas",IF(AD10="B","Está próximo al nivel esperado para lo cual requiere acompañamiento durante un tiempo razonable",IF(AD10= "C","No logro el desarrollo de las competencias",))))) -> No presenta evidencias para su calificación | AX10: =IF(C10="","",IF(C10="AD",3,IF(C10="A",2,IF(C10="B",1,IF(C10="C",0))))) | AY10: =IF(D10="","",IF(D10="AD",3,IF(D10="A",2,IF(D10="B",1,IF(D10="C",0))))) | AZ10: =IF(E10="","",IF(E10="AD",3,IF(E10="A",2,IF(E10="B",1,IF(E10="C",0))))) | BA10: =IF(F10="","",IF(F10="AD",3,IF(F10="A",2,IF(F10="B",1,IF(F10="C",0))))) | BB10: =IF(G10="","",IF(G10="AD",3,IF(G10="A",2,IF(G10="B",1,IF(G10="C",0))))) | BC10: =IF(H10="","",IF(H10="AD",3,IF(H10="A",2,IF(H10="B",1,IF(H10="C",0))))) | BD10: =IF(B10="","",IF(COUNT(AX10:BC10)=0,"",ROUND(AVERAGE(AX10:BC10),0))) | BE10: =IF(K10="","",IF(K10="AD",3,IF(K10="A",2,IF(K10="B",1,IF(K10="C",0))))) | BF10: =IF(L10="","",IF(L10="AD",3,IF(L10="A",2,IF(L10="B",1,IF(L10="C",0))))) | BG10: =IF(M10="","",IF(M10="AD",3,IF(M10="A",2,IF(M10="B",1,IF(M10="C",0))))) | BH10: =IF(N10="","",IF(N10="AD",3,IF(N10="A",2,IF(N10="B",1,IF(N10="C",0))))) | BI10: =IF(O10="","",IF(O10="AD",3,IF(O10="A",2,IF(O10="B",1,IF(O10="C",0))))) | BJ10: =IF(B10="","",IF(COUNT(BE10:BI10)=0,"",ROUND(AVERAGE(BE10:BI10),0))) | BK10: =IF(R10="","",IF(R10="AD",3,IF(R10="A",2,IF(R10="B",1,IF(R10="C",0))))) | BL10: =IF(S10="","",IF(S10="AD",3,IF(S10="A",2,IF(S10="B",1,IF(S10="C",0))))) | BM10: =IF(T10="","",IF(T10="AD",3,IF(T10="A",2,IF(T10="B",1,IF(T10="C",0))))) | BN10: =IF(U10="","",IF(U10="AD",3,IF(U10="A",2,IF(U10="B",1,IF(U10="C",0))))) | BO10: =IF(B10="","",IF(COUNT(BK10:BN10)=0,"",ROUND(AVERAGE(BK10:BN10),0))) | BP10: =IF(X10="","",IF(X10="AD",3,IF(X10="A",2,IF(X10="B",1,IF(X10="C",0))))) | BQ10: =IF(Y10="","",IF(Y10="AD",3,IF(Y10="A",2,IF(Y10="B",1,IF(Y10="C",0))))) | BR10: =IF(Z10="","",IF(Z10="AD",3,IF(Z10="A",2,IF(Z10="B",1,IF(Z10="C",0))))) | BS10: =IF(AA10="","",IF(AA10="AD",3,IF(AA10="A",2,IF(AA10="B",1,IF(AA10="C",0))))) | BT10: =IF(B10="","",IF(COUNT(BP10:BS10)=0,"",ROUND(AVERAGE(BP10:BS10),0))) | BU10: =IF(ISERROR(AVERAGE(BD10,BJ10,BO10,BT10)),"",ROUND(AVERAGE(BD10,BJ10,BO10,BT10),0)) | BV10: =IF(AE10="","",IF(AE10="AD",3,IF(AE10="A",2,IF(AE10="B",1,IF(AE10="C",0))))) | BW10: =IF(AF10="","",IF(AF10="AD",3,IF(AF10="A",2,IF(AF10="B",1,IF(AF10="C",0))))) | BX10: =IF(AG10="","",IF(AG10="AD",3,IF(AG10="A",2,IF(AG10="B",1,IF(AG10="C",0))))) | BY10: =IF(AH10="","",IF(AH10="AD",3,IF(AH10="A",2,IF(AH10="B",1,IF(AH10="C",0))))) | BZ10: =IF(B10="","",IF(COUNT(BV10:BY10)=0,"",ROUND(AVERAGE(BV10:BY10),0))) | CA10: =IF(AJ10="","",IF(AJ10="AD",3,IF(AJ10="A",2,IF(AJ10="B",1,IF(AJ10="C",0))))) | CB10: =IF(AK10="","",IF(AK10="AD",3,IF(AK10="A",2,IF(AK10="B",1,IF(AK10="C",0))))) | CC10: =IF(AL10="","",IF(AL10="AD",3,IF(AL10="A",2,IF(AL10="B",1,IF(AL10="C",0))))) | CD10: =IF(B10="","",IF(COUNT(CA10:CC10)=0,"",ROUND(AVERAGE(CA10:CC10),0)))
A11: 2 | B11: ='Datos '!D9 -> 0 | I11: =IF(BD11="","",IF(BD11=3,"AD",IF(BD11=2, "A",IF(BD11= 1, "B",IF(BD11= 0, "C"))))) | P11: =IF(BJ11="","",IF(BJ11=3,"AD",IF(BJ11=2, "A",IF(BJ11= 1, "B",IF(BJ11= 0, "C"))))) | V11: =IF(BO11="","",IF(BO11=3,"AD",IF(BO11=2, "A",IF(BO11= 1, "B",IF(BO11= 0, "C"))))) | AB11: =IF(BT11="","",IF(BT11=3,"AD",IF(BT11=2, "A",IF(BT11= 1, "B",IF(BT11= 0, "C"))))) | AD11: =IF(BU11="","",IF(BU11=3,"AD",IF(BU11=2, "A",IF(BU11= 1, "B",IF(BU11= 0, "C"))))) | AI11: =IF(BZ11="","",IF(BZ11=3,"AD",IF(BZ11=2, "A",IF(BZ11= 1, "B",IF(BZ11= 0, "C"))))) | AM11: =IF(CD11="","",IF(CD11=3,"AD",IF(CD11=2, "A",IF(CD11= 1, "B",IF(CD11= 0, "C"))))) | AN11: =IF(AD11="","No presenta evidencias para su calificación",IF(AD11="AD","Demuestra aprendizaje que van más allá del nivel esperado",IF(AD11="A","Demuestra manejo satisfactorio en todas las tareas propuestas",IF(AD11="B","Está próximo al nivel esperado para lo cual requiere acompañamiento durante un tiempo razonable",IF(AD11= "C","No logro el desarrollo de las competencias",))))) -> No presenta evidencias para su calificación | AX11: =IF(C11="","",IF(C11="AD",3,IF(C11="A",2,IF(C11="B",1,IF(C11="C",0))))) | AY11: =IF(D11="","",IF(D11="AD",3,IF(D11="A",2,IF(D11="B",1,IF(D11="C",0))))) | AZ11: =IF(E11="","",IF(E11="AD",3,IF(E11="A",2,IF(E11="B",1,IF(E11="C",0))))) | BA11: =IF(F11="","",IF(F11="AD",3,IF(F11="A",2,IF(F11="B",1,IF(F11="C",0))))) | BB11: =IF(G11="","",IF(G11="AD",3,IF(G11="A",2,IF(G11="B",1,IF(G11="C",0))))) | BC11: =IF(H11="","",IF(H11="AD",3,IF(H11="A",2,IF(H11="B",1,IF(H11="C",0))))) | BD11: =IF(B11="","",IF(COUNT(AX11:BC11)=0,"",ROUND(AVERAGE(AX11:BC11),0))) | BE11: =IF(K11="","",IF(K11="AD",3,IF(K11="A",2,IF(K11="B",1,IF(K11="C",0))))) | BF11: =IF(L11="","",IF(L11="AD",3,IF(L11="A",2,IF(L11="B",1,IF(L11="C",0))))) | BG11: =IF(M11="","",IF(M11="AD",3,IF(M11="A",2,IF(M11="B",1,IF(M11="C",0))))) | BH11: =IF(N11="","",IF(N11="AD",3,IF(N11="A",2,IF(N11="B",1,IF(N11="C",0))))) | BI11: =IF(O11="","",IF(O11="AD",3,IF(O11="A",2,IF(O11="B",1,IF(O11="C",0))))) | BJ11: =IF(B11="","",IF(COUNT(BE11:BI11)=0,"",ROUND(AVERAGE(BE11:BI11),0))) | BK11: =IF(R11="","",IF(R11="AD",3,IF(R11="A",2,IF(R11="B",1,IF(R11="C",0))))) | BL11: =IF(S11="","",IF(S11="AD",3,IF(S11="A",2,IF(S11="B",1,IF(S11="C",0))))) | BM11: =IF(T11="","",IF(T11="AD",3,IF(T11="A",2,IF(T11="B",1,IF(T11="C",0))))) | BN11: =IF(U11="","",IF(U11="AD",3,IF(U11="A",2,IF(U11="B",1,IF(U11="C",0))))) | BO11: =IF(B11="","",IF(COUNT(BK11:BN11)=0,"",ROUND(AVERAGE(BK11:BN11),0))) | BP11: =IF(X11="","",IF(X11="AD",3,IF(X11="A",2,IF(X11="B",1,IF(X11="C",0))))) | BQ11: =IF(Y11="","",IF(Y11="AD",3,IF(Y11="A",2,IF(Y11="B",1,IF(Y11="C",0))))) | BR11: =IF(Z11="","",IF(Z11="AD",3,IF(Z11="A",2,IF(Z11="B",1,IF(Z11="C",0))))) | BS11: =IF(AA11="","",IF(AA11="AD",3,IF(AA11="A",2,IF(AA11="B",1,IF(AA11="C",0))))) | BT11: =IF(B11="","",IF(COUNT(BP11:BS11)=0,"",ROUND(AVERAGE(BP11:BS11),0))) | BU11: =IF(ISERROR(AVERAGE(BD11,BJ11,BO11,BT11)),"",ROUND(AVERAGE(BD11,BJ11,BO11,BT11),0)) | BV11: =IF(AE11="","",IF(AE11="AD",3,IF(AE11="A",2,IF(AE11="B",1,IF(AE11="C",0))))) | BW11: =IF(AF11="","",IF(AF11="AD",3,IF(AF11="A",2,IF(AF11="B",1,IF(AF11="C",0))))) | BX11: =IF(AG11="","",IF(AG11="AD",3,IF(AG11="A",2,IF(AG11="B",1,IF(AG11="C",0))))) | BY11: =IF(AH11="","",IF(AH11="AD",3,IF(AH11="A",2,IF(AH11="B",1,IF(AH11="C",0))))) | BZ11: =IF(B11="","",IF(COUNT(BV11:BY11)=0,"",ROUND(AVERAGE(BV11:BY11),0))) | CA11: =IF(AJ11="","",IF(AJ11="AD",3,IF(AJ11="A",2,IF(AJ11="B",1,IF(AJ11="C",0))))) | CB11: =IF(AK11="","",IF(AK11="AD",3,IF(AK11="A",2,IF(AK11="B",1,IF(AK11="C",0))))) | CC11: =IF(AL11="","",IF(AL11="AD",3,IF(AL11="A",2,IF(AL11="B",1,IF(AL11="C",0))))) | CD11: =IF(B11="","",IF(COUNT(CA11:CC11)=0,"",ROUND(AVERAGE(CA11:CC11),0)))
A12: 3 | B12: ='Datos '!D10 -> 0 | I12: =IF(BD12="","",IF(BD12=3,"AD",IF(BD12=2, "A",IF(BD12= 1, "B",IF(BD12= 0, "C"))))) | P12: =IF(BJ12="","",IF(BJ12=3,"AD",IF(BJ12=2, "A",IF(BJ12= 1, "B",IF(BJ12= 0, "C"))))) | V12: =IF(BO12="","",IF(BO12=3,"AD",IF(BO12=2, "A",IF(BO12= 1, "B",IF(BO12= 0, "C"))))) | AB12: =IF(BT12="","",IF(BT12=3,"AD",IF(BT12=2, "A",IF(BT12= 1, "B",IF(BT12= 0, "C"))))) | AD12: =IF(BU12="","",IF(BU12=3,"AD",IF(BU12=2, "A",IF(BU12= 1, "B",IF(BU12= 0, "C"))))) | AI12: =IF(BZ12="","",IF(BZ12=3,"AD",IF(BZ12=2, "A",IF(BZ12= 1, "B",IF(BZ12= 0, "C"))))) | AM12: =IF(CD12="","",IF(CD12=3,"AD",IF(CD12=2, "A",IF(CD12= 1, "B",IF(CD12= 0, "C"))))) | AN12: =IF(AD12="","No presenta evidencias para su calificación",IF(AD12="AD","Demuestra aprendizaje que van más allá del nivel esperado",IF(AD12="A","Demuestra manejo satisfactorio en todas las tareas propuestas",IF(AD12="B","Está próximo al nivel esperado para lo cual requiere acompañamiento durante un tiempo razonable",IF(AD12= "C","No logro el desarrollo de las competencias",))))) -> No presenta evidencias para su calificación | AX12: =IF(C12="","",IF(C12="AD",3,IF(C12="A",2,IF(C12="B",1,IF(C12="C",0))))) | AY12: =IF(D12="","",IF(D12="AD",3,IF(D12="A",2,IF(D12="B",1,IF(D12="C",0))))) | AZ12: =IF(E12="","",IF(E12="AD",3,IF(E12="A",2,IF(E12="B",1,IF(E12="C",0))))) | BA12: =IF(F12="","",IF(F12="AD",3,IF(F12="A",2,IF(F12="B",1,IF(F12="C",0))))) | BB12: =IF(G12="","",IF(G12="AD",3,IF(G12="A",2,IF(G12="B",1,IF(G12="C",0))))) | BC12: =IF(H12="","",IF(H12="AD",3,IF(H12="A",2,IF(H12="B",1,IF(H12="C",0))))) | BD12: =IF(B12="","",IF(COUNT(AX12:BC12)=0,"",ROUND(AVERAGE(AX12:BC12),0))) | BE12: =IF(K12="","",IF(K12="AD",3,IF(K12="A",2,IF(K12="B",1,IF(K12="C",0))))) | BF12: =IF(L12="","",IF(L12="AD",3,IF(L12="A",2,IF(L12="B",1,IF(L12="C",0))))) | BG12: =IF(M12="","",IF(M12="AD",3,IF(M12="A",2,IF(M12="B",1,IF(M12="C",0))))) | BH12: =IF(N12="","",IF(N12="AD",3,IF(N12="A",2,IF(N12="B",1,IF(N12="C",0))))) | BI12: =IF(O12="","",IF(O12="AD",3,IF(O12="A",2,IF(O12="B",1,IF(O12="C",0))))) | BJ12: =IF(B12="","",IF(COUNT(BE12:BI12)=0,"",ROUND(AVERAGE(BE12:BI12),0))) | BK12: =IF(R12="","",IF(R12="AD",3,IF(R12="A",2,IF(R12="B",1,IF(R12="C",0))))) | BL12: =IF(S12="","",IF(S12="AD",3,IF(S12="A",2,IF(S12="B",1,IF(S12="C",0))))) | BM12: =IF(T12="","",IF(T12="AD",3,IF(T12="A",2,IF(T12="B",1,IF(T12="C",0))))) | BN12: =IF(U12="","",IF(U12="AD",3,IF(U12="A",2,IF(U12="B",1,IF(U12="C",0))))) | BO12: =IF(B12="","",IF(COUNT(BK12:BN12)=0,"",ROUND(AVERAGE(BK12:BN12),0))) | BP12: =IF(X12="","",IF(X12="AD",3,IF(X12="A",2,IF(X12="B",1,IF(X12="C",0))))) | BQ12: =IF(Y12="","",IF(Y12="AD",3,IF(Y12="A",2,IF(Y12="B",1,IF(Y12="C",0))))) | BR12: =IF(Z12="","",IF(Z12="AD",3,IF(Z12="A",2,IF(Z12="B",1,IF(Z12="C",0))))) | BS12: =IF(AA12="","",IF(AA12="AD",3,IF(AA12="A",2,IF(AA12="B",1,IF(AA12="C",0))))) | BT12: =IF(B12="","",IF(COUNT(BP12:BS12)=0,"",ROUND(AVERAGE(BP12:BS12),0))) | BU12: =IF(ISERROR(AVERAGE(BD12,BJ12,BO12,BT12)),"",ROUND(AVERAGE(BD12,BJ12,BO12,BT12),0)) | BV12: =IF(AE12="","",IF(AE12="AD",3,IF(AE12="A",2,IF(AE12="B",1,IF(AE12="C",0))))) | BW12: =IF(AF12="","",IF(AF12="AD",3,IF(AF12="A",2,IF(AF12="B",1,IF(AF12="C",0))))) | BX12: =IF(AG12="","",IF(AG12="AD",3,IF(AG12="A",2,IF(AG12="B",1,IF(AG12="C",0))))) | BY12: =IF(AH12="","",IF(AH12="AD",3,IF(AH12="A",2,IF(AH12="B",1,IF(AH12="C",0))))) | BZ12: =IF(B12="","",IF(COUNT(BV12:BY12)=0,"",ROUND(AVERAGE(BV12:BY12),0))) | CA12: =IF(AJ12="","",IF(AJ12="AD",3,IF(AJ12="A",2,IF(AJ12="B",1,IF(AJ12="C",0))))) | CB12: =IF(AK12="","",IF(AK12="AD",3,IF(AK12="A",2,IF(AK12="B",1,IF(AK12="C",0))))) | CC12: =IF(AL12="","",IF(AL12="AD",3,IF(AL12="A",2,IF(AL12="B",1,IF(AL12="C",0))))) | CD12: =IF(B12="","",IF(COUNT(CA12:CC12)=0,"",ROUND(AVERAGE(CA12:CC12),0)))
A13: 4 | B13: ='Datos '!D11 -> 0 | I13: =IF(BD13="","",IF(BD13=3,"AD",IF(BD13=2, "A",IF(BD13= 1, "B",IF(BD13= 0, "C"))))) | P13: =IF(BJ13="","",IF(BJ13=3,"AD",IF(BJ13=2, "A",IF(BJ13= 1, "B",IF(BJ13= 0, "C"))))) | V13: =IF(BO13="","",IF(BO13=3,"AD",IF(BO13=2, "A",IF(BO13= 1, "B",IF(BO13= 0, "C"))))) | AB13: =IF(BT13="","",IF(BT13=3,"AD",IF(BT13=2, "A",IF(BT13= 1, "B",IF(BT13= 0, "C"))))) | AD13: =IF(BU13="","",IF(BU13=3,"AD",IF(BU13=2, "A",IF(BU13= 1, "B",IF(BU13= 0, "C"))))) | AI13: =IF(BZ13="","",IF(BZ13=3,"AD",IF(BZ13=2, "A",IF(BZ13= 1, "B",IF(BZ13= 0, "C"))))) | AM13: =IF(CD13="","",IF(CD13=3,"AD",IF(CD13=2, "A",IF(CD13= 1, "B",IF(CD13= 0, "C"))))) | AN13: =IF(AD13="","No presenta evidencias para su calificación",IF(AD13="AD","Demuestra aprendizaje que van más allá del nivel esperado",IF(AD13="A","Demuestra manejo satisfactorio en todas las tareas propuestas",IF(AD13="B","Está próximo al nivel esperado para lo cual requiere acompañamiento durante un tiempo razonable",IF(AD13= "C","No logro el desarrollo de las competencias",))))) -> No presenta evidencias para su calificación | AX13: =IF(C13="","",IF(C13="AD",3,IF(C13="A",2,IF(C13="B",1,IF(C13="C",0))))) | AY13: =IF(D13="","",IF(D13="AD",3,IF(D13="A",2,IF(D13="B",1,IF(D13="C",0))))) | AZ13: =IF(E13="","",IF(E13="AD",3,IF(E13="A",2,IF(E13="B",1,IF(E13="C",0))))) | BA13: =IF(F13="","",IF(F13="AD",3,IF(F13="A",2,IF(F13="B",1,IF(F13="C",0))))) | BB13: =IF(G13="","",IF(G13="AD",3,IF(G13="A",2,IF(G13="B",1,IF(G13="C",0))))) | BC13: =IF(H13="","",IF(H13="AD",3,IF(H13="A",2,IF(H13="B",1,IF(H13="C",0))))) | BD13: =IF(B13="","",IF(COUNT(AX13:BC13)=0,"",ROUND(AVERAGE(AX13:BC13),0))) | BE13: =IF(K13="","",IF(K13="AD",3,IF(K13="A",2,IF(K13="B",1,IF(K13="C",0))))) | BF13: =IF(L13="","",IF(L13="AD",3,IF(L13="A",2,IF(L13="B",1,IF(L13="C",0))))) | BG13: =IF(M13="","",IF(M13="AD",3,IF(M13="A",2,IF(M13="B",1,IF(M13="C",0))))) | BH13: =IF(N13="","",IF(N13="AD",3,IF(N13="A",2,IF(N13="B",1,IF(N13="C",0))))) | BI13: =IF(O13="","",IF(O13="AD",3,IF(O13="A",2,IF(O13="B",1,IF(O13="C",0))))) | BJ13: =IF(B13="","",IF(COUNT(BE13:BI13)=0,"",ROUND(AVERAGE(BE13:BI13),0))) | BK13: =IF(R13="","",IF(R13="AD",3,IF(R13="A",2,IF(R13="B",1,IF(R13="C",0))))) | BL13: =IF(S13="","",IF(S13="AD",3,IF(S13="A",2,IF(S13="B",1,IF(S13="C",0))))) | BM13: =IF(T13="","",IF(T13="AD",3,IF(T13="A",2,IF(T13="B",1,IF(T13="C",0))))) | BN13: =IF(U13="","",IF(U13="AD",3,IF(U13="A",2,IF(U13="B",1,IF(U13="C",0))))) | BO13: =IF(B13="","",IF(COUNT(BK13:BN13)=0,"",ROUND(AVERAGE(BK13:BN13),0))) | BP13: =IF(X13="","",IF(X13="AD",3,IF(X13="A",2,IF(X13="B",1,IF(X13="C",0))))) | BQ13: =IF(Y13="","",IF(Y13="AD",3,IF(Y13="A",2,IF(Y13="B",1,IF(Y13="C",0))))) | BR13: =IF(Z13="","",IF(Z13="AD",3,IF(Z13="A",2,IF(Z13="B",1,IF(Z13="C",0))))) | BS13: =IF(AA13="","",IF(AA13="AD",3,IF(AA13="A",2,IF(AA13="B",1,IF(AA13="C",0))))) | BT13: =IF(B13="","",IF(COUNT(BP13:BS13)=0,"",ROUND(AVERAGE(BP13:BS13),0))) | BU13: =IF(ISERROR(AVERAGE(BD13,BJ13,BO13,BT13)),"",ROUND(AVERAGE(BD13,BJ13,BO13,BT13),0)) | BV13: =IF(AE13="","",IF(AE13="AD",3,IF(AE13="A",2,IF(AE13="B",1,IF(AE13="C",0))))) | BW13: =IF(AF13="","",IF(AF13="AD",3,IF(AF13="A",2,IF(AF13="B",1,IF(AF13="C",0))))) | BX13: =IF(AG13="","",IF(AG13="AD",3,IF(AG13="A",2,IF(AG13="B",1,IF(AG13="C",0))))) | BY13: =IF(AH13="","",IF(AH13="AD",3,IF(AH13="A",2,IF(AH13="B",1,IF(AH13="C",0))))) | BZ13: =IF(B13="","",IF(COUNT(BV13:BY13)=0,"",ROUND(AVERAGE(BV13:BY13),0))) | CA13: =IF(AJ13="","",IF(AJ13="AD",3,IF(AJ13="A",2,IF(AJ13="B",1,IF(AJ13="C",0))))) | CB13: =IF(AK13="","",IF(AK13="AD",3,IF(AK13="A",2,IF(AK13="B",1,IF(AK13="C",0))))) | CC13: =IF(AL13="","",IF(AL13="AD",3,IF(AL13="A",2,IF(AL13="B",1,IF(AL13="C",0))))) | CD13: =IF(B13="","",IF(COUNT(CA13:CC13)=0,"",ROUND(AVERAGE(CA13:CC13),0)))
A14: 5 | B14: ='Datos '!D12 -> 0 | I14: =IF(BD14="","",IF(BD14=3,"AD",IF(BD14=2, "A",IF(BD14= 1, "B",IF(BD14= 0, "C"))))) | P14: =IF(BJ14="","",IF(BJ14=3,"AD",IF(BJ14=2, "A",IF(BJ14= 1, "B",IF(BJ14= 0, "C"))))) | V14: =IF(BO14="","",IF(BO14=3,"AD",IF(BO14=2, "A",IF(BO14= 1, "B",IF(BO14= 0, "C"))))) | AB14: =IF(BT14="","",IF(BT14=3,"AD",IF(BT14=2, "A",IF(BT14= 1, "B",IF(BT14= 0, "C"))))) | AD14: =IF(BU14="","",IF(BU14=3,"AD",IF(BU14=2, "A",IF(BU14= 1, "B",IF(BU14= 0, "C"))))) | AI14: =IF(BZ14="","",IF(BZ14=3,"AD",IF(BZ14=2, "A",IF(BZ14= 1, "B",IF(BZ14= 0, "C"))))) | AM14: =IF(CD14="","",IF(CD14=3,"AD",IF(CD14=2, "A",IF(CD14= 1, "B",IF(CD14= 0, "C"))))) | AN14: =IF(AD14="","No presenta evidencias para su calificación",IF(AD14="AD","Demuestra aprendizaje que van más allá del nivel esperado",IF(AD14="A","Demuestra manejo satisfactorio en todas las tareas propuestas",IF(AD14="B","Está próximo al nivel esperado para lo cual requiere acompañamiento durante un tiempo razonable",IF(AD14= "C","No logro el desarrollo de las competencias",))))) -> No presenta evidencias para su calificación | AX14: =IF(C14="","",IF(C14="AD",3,IF(C14="A",2,IF(C14="B",1,IF(C14="C",0))))) | AY14: =IF(D14="","",IF(D14="AD",3,IF(D14="A",2,IF(D14="B",1,IF(D14="C",0))))) | AZ14: =IF(E14="","",IF(E14="AD",3,IF(E14="A",2,IF(E14="B",1,IF(E14="C",0))))) | BA14: =IF(F14="","",IF(F14="AD",3,IF(F14="A",2,IF(F14="B",1,IF(F14="C",0))))) | BB14: =IF(G14="","",IF(G14="AD",3,IF(G14="A",2,IF(G14="B",1,IF(G14="C",0))))) | BC14: =IF(H14="","",IF(H14="AD",3,IF(H14="A",2,IF(H14="B",1,IF(H14="C",0))))) | BD14: =IF(B14="","",IF(COUNT(AX14:BC14)=0,"",ROUND(AVERAGE(AX14:BC14),0))) | BE14: =IF(K14="","",IF(K14="AD",3,IF(K14="A",2,IF(K14="B",1,IF(K14="C",0))))) | BF14: =IF(L14="","",IF(L14="AD",3,IF(L14="A",2,IF(L14="B",1,IF(L14="C",0))))) | BG14: =IF(M14="","",IF(M14="AD",3,IF(M14="A",2,IF(M14="B",1,IF(M14="C",0))))) | BH14: =IF(N14="","",IF(N14="AD",3,IF(N14="A",2,IF(N14="B",1,IF(N14="C",0))))) | BI14: =IF(O14="","",IF(O14="AD",3,IF(O14="A",2,IF(O14="B",1,IF(O14="C",0))))) | BJ14: =IF(B14="","",IF(COUNT(BE14:BI14)=0,"",ROUND(AVERAGE(BE14:BI14),0))) | BK14: =IF(R14="","",IF(R14="AD",3,IF(R14="A",2,IF(R14="B",1,IF(R14="C",0))))) | BL14: =IF(S14="","",IF(S14="AD",3,IF(S14="A",2,IF(S14="B",1,IF(S14="C",0))))) | BM14: =IF(T14="","",IF(T14="AD",3,IF(T14="A",2,IF(T14="B",1,IF(T14="C",0))))) | BN14: =IF(U14="","",IF(U14="AD",3,IF(U14="A",2,IF(U14="B",1,IF(U14="C",0))))) | BO14: =IF(B14="","",IF(COUNT(BK14:BN14)=0,"",ROUND(AVERAGE(BK14:BN14),0))) | BP14: =IF(X14="","",IF(X14="AD",3,IF(X14="A",2,IF(X14="B",1,IF(X14="C",0))))) | BQ14: =IF(Y14="","",IF(Y14="AD",3,IF(Y14="A",2,IF(Y14="B",1,IF(Y14="C",0))))) | BR14: =IF(Z14="","",IF(Z14="AD",3,IF(Z14="A",2,IF(Z14="B",1,IF(Z14="C",0))))) | BS14: =IF(AA14="","",IF(AA14="AD",3,IF(AA14="A",2,IF(AA14="B",1,IF(AA14="C",0))))) | BT14: =IF(B14="","",IF(COUNT(BP14:BS14)=0,"",ROUND(AVERAGE(BP14:BS14),0))) | BU14: =IF(ISERROR(AVERAGE(BD14,BJ14,BO14,BT14)),"",ROUND(AVERAGE(BD14,BJ14,BO14,BT14),0)) | BV14: =IF(AE14="","",IF(AE14="AD",3,IF(AE14="A",2,IF(AE14="B",1,IF(AE14="C",0))))) | BW14: =IF(AF14="","",IF(AF14="AD",3,IF(AF14="A",2,IF(AF14="B",1,IF(AF14="C",0))))) | BX14: =IF(AG14="","",IF(AG14="AD",3,IF(AG14="A",2,IF(AG14="B",1,IF(AG14="C",0))))) | BY14: =IF(AH14="","",IF(AH14="AD",3,IF(AH14="A",2,IF(AH14="B",1,IF(AH14="C",0))))) | BZ14: =IF(B14="","",IF(COUNT(BV14:BY14)=0,"",ROUND(AVERAGE(BV14:BY14),0))) | CA14: =IF(AJ14="","",IF(AJ14="AD",3,IF(AJ14="A",2,IF(AJ14="B",1,IF(AJ14="C",0))))) | CB14: =IF(AK14="","",IF(AK14="AD",3,IF(AK14="A",2,IF(AK14="B",1,IF(AK14="C",0))))) | CC14: =IF(AL14="","",IF(AL14="AD",3,IF(AL14="A",2,IF(AL14="B",1,IF(AL14="C",0))))) | CD14: =IF(B14="","",IF(COUNT(CA14:CC14)=0,"",ROUND(AVERAGE(CA14:CC14),0)))
A15: 6 | B15: ='Datos '!D13 -> 0 | I15: =IF(BD15="","",IF(BD15=3,"AD",IF(BD15=2, "A",IF(BD15= 1, "B",IF(BD15= 0, "C"))))) | P15: =IF(BJ15="","",IF(BJ15=3,"AD",IF(BJ15=2, "A",IF(BJ15= 1, "B",IF(BJ15= 0, "C"))))) | V15: =IF(BO15="","",IF(BO15=3,"AD",IF(BO15=2, "A",IF(BO15= 1, "B",IF(BO15= 0, "C"))))) | AB15: =IF(BT15="","",IF(BT15=3,"AD",IF(BT15=2, "A",IF(BT15= 1, "B",IF(BT15= 0, "C"))))) | AD15: =IF(BU15="","",IF(BU15=3,"AD",IF(BU15=2, "A",IF(BU15= 1, "B",IF(BU15= 0, "C"))))) | AI15: =IF(BZ15="","",IF(BZ15=3,"AD",IF(BZ15=2, "A",IF(BZ15= 1, "B",IF(BZ15= 0, "C"))))) | AM15: =IF(CD15="","",IF(CD15=3,"AD",IF(CD15=2, "A",IF(CD15= 1, "B",IF(CD15= 0, "C"))))) | AN15: =IF(AD15="","No presenta evidencias para su calificación",IF(AD15="AD","Demuestra aprendizaje que van más allá del nivel esperado",IF(AD15="A","Demuestra manejo satisfactorio en todas las tareas propuestas",IF(AD15="B","Está próximo al nivel esperado para lo cual requiere acompañamiento durante un tiempo razonable",IF(AD15= "C","No logro el desarrollo de las competencias",))))) -> No presenta evidencias para su calificación | AX15: =IF(C15="","",IF(C15="AD",3,IF(C15="A",2,IF(C15="B",1,IF(C15="C",0))))) | AY15: =IF(D15="","",IF(D15="AD",3,IF(D15="A",2,IF(D15="B",1,IF(D15="C",0))))) | AZ15: =IF(E15="","",IF(E15="AD",3,IF(E15="A",2,IF(E15="B",1,IF(E15="C",0))))) | BA15: =IF(F15="","",IF(F15="AD",3,IF(F15="A",2,IF(F15="B",1,IF(F15="C",0))))) | BB15: =IF(G15="","",IF(G15="AD",3,IF(G15="A",2,IF(G15="B",1,IF(G15="C",0))))) | BC15: =IF(H15="","",IF(H15="AD",3,IF(H15="A",2,IF(H15="B",1,IF(H15="C",0))))) | BD15: =IF(B15="","",IF(COUNT(AX15:BC15)=0,"",ROUND(AVERAGE(AX15:BC15),0))) | BE15: =IF(K15="","",IF(K15="AD",3,IF(K15="A",2,IF(K15="B",1,IF(K15="C",0))))) | BF15: =IF(L15="","",IF(L15="AD",3,IF(L15="A",2,IF(L15="B",1,IF(L15="C",0))))) | BG15: =IF(M15="","",IF(M15="AD",3,IF(M15="A",2,IF(M15="B",1,IF(M15="C",0))))) | BH15: =IF(N15="","",IF(N15="AD",3,IF(N15="A",2,IF(N15="B",1,IF(N15="C",0))))) | BI15: =IF(O15="","",IF(O15="AD",3,IF(O15="A",2,IF(O15="B",1,IF(O15="C",0))))) | BJ15: =IF(B15="","",IF(COUNT(BE15:BI15)=0,"",ROUND(AVERAGE(BE15:BI15),0))) | BK15: =IF(R15="","",IF(R15="AD",3,IF(R15="A",2,IF(R15="B",1,IF(R15="C",0))))) | BL15: =IF(S15="","",IF(S15="AD",3,IF(S15="A",2,IF(S15="B",1,IF(S15="C",0))))) | BM15: =IF(T15="","",IF(T15="AD",3,IF(T15="A",2,IF(T15="B",1,IF(T15="C",0))))) | BN15: =IF(U15="","",IF(U15="AD",3,IF(U15="A",2,IF(U15="B",1,IF(U15="C",0))))) | BO15: =IF(B15="","",IF(COUNT(BK15:BN15)=0,"",ROUND(AVERAGE(BK15:BN15),0))) | BP15: =IF(X15="","",IF(X15="AD",3,IF(X15="A",2,IF(X15="B",1,IF(X15="C",0))))) | BQ15: =IF(Y15="","",IF(Y15="AD",3,IF(Y15="A",2,IF(Y15="B",1,IF(Y15="C",0))))) | BR15: =IF(Z15="","",IF(Z15="AD",3,IF(Z15="A",2,IF(Z15="B",1,IF(Z15="C",0))))) | BS15: =IF(AA15="","",IF(AA15="AD",3,IF(AA15="A",2,IF(AA15="B",1,IF(AA15="C",0))))) | BT15: =IF(B15="","",IF(COUNT(BP15:BS15)=0,"",ROUND(AVERAGE(BP15:BS15),0))) | BU15: =IF(ISERROR(AVERAGE(BD15,BJ15,BO15,BT15)),"",ROUND(AVERAGE(BD15,BJ15,BO15,BT15),0)) | BV15: =IF(AE15="","",IF(AE15="AD",3,IF(AE15="A",2,IF(AE15="B",1,IF(AE15="C",0))))) | BW15: =IF(AF15="","",IF(AF15="AD",3,IF(AF15="A",2,IF(AF15="B",1,IF(AF15="C",0))))) | BX15: =IF(AG15="","",IF(AG15="AD",3,IF(AG15="A",2,IF(AG15="B",1,IF(AG15="C",0))))) | BY15: =IF(AH15="","",IF(AH15="AD",3,IF(AH15="A",2,IF(AH15="B",1,IF(AH15="C",0))))) | BZ15: =IF(B15="","",IF(COUNT(BV15:BY15)=0,"",ROUND(AVERAGE(BV15:BY15),0))) | CA15: =IF(AJ15="","",IF(AJ15="AD",3,IF(AJ15="A",2,IF(AJ15="B",1,IF(AJ15="C",0))))) | CB15: =IF(AK15="","",IF(AK15="AD",3,IF(AK15="A",2,IF(AK15="B",1,IF(AK15="C",0))))) | CC15: =IF(AL15="","",IF(AL15="AD",3,IF(AL15="A",2,IF(AL15="B",1,IF(AL15="C",0))))) | CD15: =IF(B15="","",IF(COUNT(CA15:CC15)=0,"",ROUND(AVERAGE(CA15:CC15),0)))
A16: 7 | B16: ='Datos '!D14 -> 0 | I16: =IF(BD16="","",IF(BD16=3,"AD",IF(BD16=2, "A",IF(BD16= 1, "B",IF(BD16= 0, "C"))))) | P16: =IF(BJ16="","",IF(BJ16=3,"AD",IF(BJ16=2, "A",IF(BJ16= 1, "B",IF(BJ16= 0, "C"))))) | V16: =IF(BO16="","",IF(BO16=3,"AD",IF(BO16=2, "A",IF(BO16= 1, "B",IF(BO16= 0, "C"))))) | AB16: =IF(BT16="","",IF(BT16=3,"AD",IF(BT16=2, "A",IF(BT16= 1, "B",IF(BT16= 0, "C"))))) | AD16: =IF(BU16="","",IF(BU16=3,"AD",IF(BU16=2, "A",IF(BU16= 1, "B",IF(BU16= 0, "C"))))) | AI16: =IF(BZ16="","",IF(BZ16=3,"AD",IF(BZ16=2, "A",IF(BZ16= 1, "B",IF(BZ16= 0, "C"))))) | AM16: =IF(CD16="","",IF(CD16=3,"AD",IF(CD16=2, "A",IF(CD16= 1, "B",IF(CD16= 0, "C"))))) | AN16: =IF(AD16="","No presenta evidencias para su calificación",IF(AD16="AD","Demuestra aprendizaje que van más allá del nivel esperado",IF(AD16="A","Demuestra manejo satisfactorio en todas las tareas propuestas",IF(AD16="B","Está próximo al nivel esperado para lo cual requiere acompañamiento durante un tiempo razonable",IF(AD16= "C","No logro el desarrollo de las competencias",))))) -> No presenta evidencias para su calificación | AX16: =IF(C16="","",IF(C16="AD",3,IF(C16="A",2,IF(C16="B",1,IF(C16="C",0))))) | AY16: =IF(D16="","",IF(D16="AD",3,IF(D16="A",2,IF(D16="B",1,IF(D16="C",0))))) | AZ16: =IF(E16="","",IF(E16="AD",3,IF(E16="A",2,IF(E16="B",1,IF(E16="C",0))))) | BA16: =IF(F16="","",IF(F16="AD",3,IF(F16="A",2,IF(F16="B",1,IF(F16="C",0))))) | BB16: =IF(G16="","",IF(G16="AD",3,IF(G16="A",2,IF(G16="B",1,IF(G16="C",0))))) | BC16: =IF(H16="","",IF(H16="AD",3,IF(H16="A",2,IF(H16="B",1,IF(H16="C",0))))) | BD16: =IF(B16="","",IF(COUNT(AX16:BC16)=0,"",ROUND(AVERAGE(AX16:BC16),0))) | BE16: =IF(K16="","",IF(K16="AD",3,IF(K16="A",2,IF(K16="B",1,IF(K16="C",0))))) | BF16: =IF(L16="","",IF(L16="AD",3,IF(L16="A",2,IF(L16="B",1,IF(L16="C",0))))) | BG16: =IF(M16="","",IF(M16="AD",3,IF(M16="A",2,IF(M16="B",1,IF(M16="C",0))))) | BH16: =IF(N16="","",IF(N16="AD",3,IF(N16="A",2,IF(N16="B",1,IF(N16="C",0))))) | BI16: =IF(O16="","",IF(O16="AD",3,IF(O16="A",2,IF(O16="B",1,IF(O16="C",0))))) | BJ16: =IF(B16="","",IF(COUNT(BE16:BI16)=0,"",ROUND(AVERAGE(BE16:BI16),0))) | BK16: =IF(R16="","",IF(R16="AD",3,IF(R16="A",2,IF(R16="B",1,IF(R16="C",0))))) | BL16: =IF(S16="","",IF(S16="AD",3,IF(S16="A",2,IF(S16="B",1,IF(S16="C",0))))) | BM16: =IF(T16="","",IF(T16="AD",3,IF(T16="A",2,IF(T16="B",1,IF(T16="C",0))))) | BN16: =IF(U16="","",IF(U16="AD",3,IF(U16="A",2,IF(U16="B",1,IF(U16="C",0))))) | BO16: =IF(B16="","",IF(COUNT(BK16:BN16)=0,"",ROUND(AVERAGE(BK16:BN16),0))) | BP16: =IF(X16="","",IF(X16="AD",3,IF(X16="A",2,IF(X16="B",1,IF(X16="C",0))))) | BQ16: =IF(Y16="","",IF(Y16="AD",3,IF(Y16="A",2,IF(Y16="B",1,IF(Y16="C",0))))) | BR16: =IF(Z16="","",IF(Z16="AD",3,IF(Z16="A",2,IF(Z16="B",1,IF(Z16="C",0))))) | BS16: =IF(AA16="","",IF(AA16="AD",3,IF(AA16="A",2,IF(AA16="B",1,IF(AA16="C",0))))) | BT16: =IF(B16="","",IF(COUNT(BP16:BS16)=0,"",ROUND(AVERAGE(BP16:BS16),0))) | BU16: =IF(ISERROR(AVERAGE(BD16,BJ16,BO16,BT16)),"",ROUND(AVERAGE(BD16,BJ16,BO16,BT16),0)) | BV16: =IF(AE16="","",IF(AE16="AD",3,IF(AE16="A",2,IF(AE16="B",1,IF(AE16="C",0))))) | BW16: =IF(AF16="","",IF(AF16="AD",3,IF(AF16="A",2,IF(AF16="B",1,IF(AF16="C",0))))) | BX16: =IF(AG16="","",IF(AG16="AD",3,IF(AG16="A",2,IF(AG16="B",1,IF(AG16="C",0))))) | BY16: =IF(AH16="","",IF(AH16="AD",3,IF(AH16="A",2,IF(AH16="B",1,IF(AH16="C",0))))) | BZ16: =IF(B16="","",IF(COUNT(BV16:BY16)=0,"",ROUND(AVERAGE(BV16:BY16),0))) | CA16: =IF(AJ16="","",IF(AJ16="AD",3,IF(AJ16="A",2,IF(AJ16="B",1,IF(AJ16="C",0))))) | CB16: =IF(AK16="","",IF(AK16="AD",3,IF(AK16="A",2,IF(AK16="B",1,IF(AK16="C",0))))) | CC16: =IF(AL16="","",IF(AL16="AD",3,IF(AL16="A",2,IF(AL16="B",1,IF(AL16="C",0))))) | CD16: =IF(B16="","",IF(COUNT(CA16:CC16)=0,"",ROUND(AVERAGE(CA16:CC16),0)))
A17: 8 | B17: ='Datos '!D15 -> 0 | I17: =IF(BD17="","",IF(BD17=3,"AD",IF(BD17=2, "A",IF(BD17= 1, "B",IF(BD17= 0, "C"))))) | P17: =IF(BJ17="","",IF(BJ17=3,"AD",IF(BJ17=2, "A",IF(BJ17= 1, "B",IF(BJ17= 0, "C"))))) | V17: =IF(BO17="","",IF(BO17=3,"AD",IF(BO17=2, "A",IF(BO17= 1, "B",IF(BO17= 0, "C"))))) | AB17: =IF(BT17="","",IF(BT17=3,"AD",IF(BT17=2, "A",IF(BT17= 1, "B",IF(BT17= 0, "C"))))) | AD17: =IF(BU17="","",IF(BU17=3,"AD",IF(BU17=2, "A",IF(BU17= 1, "B",IF(BU17= 0, "C"))))) | AI17: =IF(BZ17="","",IF(BZ17=3,"AD",IF(BZ17=2, "A",IF(BZ17= 1, "B",IF(BZ17= 0, "C"))))) | AM17: =IF(CD17="","",IF(CD17=3,"AD",IF(CD17=2, "A",IF(CD17= 1, "B",IF(CD17= 0, "C"))))) | AN17: =IF(AD17="","No presenta evidencias para su calificación",IF(AD17="AD","Demuestra aprendizaje que van más allá del nivel esperado",IF(AD17="A","Demuestra manejo satisfactorio en todas las tareas propuestas",IF(AD17="B","Está próximo al nivel esperado para lo cual requiere acompañamiento durante un tiempo razonable",IF(AD17= "C","No logro el desarrollo de las competencias",))))) -> No presenta evidencias para su calificación | AX17: =IF(C17="","",IF(C17="AD",3,IF(C17="A",2,IF(C17="B",1,IF(C17="C",0))))) | AY17: =IF(D17="","",IF(D17="AD",3,IF(D17="A",2,IF(D17="B",1,IF(D17="C",0))))) | AZ17: =IF(E17="","",IF(E17="AD",3,IF(E17="A",2,IF(E17="B",1,IF(E17="C",0))))) | BA17: =IF(F17="","",IF(F17="AD",3,IF(F17="A",2,IF(F17="B",1,IF(F17="C",0))))) | BB17: =IF(G17="","",IF(G17="AD",3,IF(G17="A",2,IF(G17="B",1,IF(G17="C",0))))) | BC17: =IF(H17="","",IF(H17="AD",3,IF(H17="A",2,IF(H17="B",1,IF(H17="C",0))))) | BD17: =IF(B17="","",IF(COUNT(AX17:BC17)=0,"",ROUND(AVERAGE(AX17:BC17),0))) | BE17: =IF(K17="","",IF(K17="AD",3,IF(K17="A",2,IF(K17="B",1,IF(K17="C",0))))) | BF17: =IF(L17="","",IF(L17="AD",3,IF(L17="A",2,IF(L17="B",1,IF(L17="C",0))))) | BG17: =IF(M17="","",IF(M17="AD",3,IF(M17="A",2,IF(M17="B",1,IF(M17="C",0))))) | BH17: =IF(N17="","",IF(N17="AD",3,IF(N17="A",2,IF(N17="B",1,IF(N17="C",0))))) | BI17: =IF(O17="","",IF(O17="AD",3,IF(O17="A",2,IF(O17="B",1,IF(O17="C",0))))) | BJ17: =IF(B17="","",IF(COUNT(BE17:BI17)=0,"",ROUND(AVERAGE(BE17:BI17),0))) | BK17: =IF(R17="","",IF(R17="AD",3,IF(R17="A",2,IF(R17="B",1,IF(R17="C",0))))) | BL17: =IF(S17="","",IF(S17="AD",3,IF(S17="A",2,IF(S17="B",1,IF(S17="C",0))))) | BM17: =IF(T17="","",IF(T17="AD",3,IF(T17="A",2,IF(T17="B",1,IF(T17="C",0))))) | BN17: =IF(U17="","",IF(U17="AD",3,IF(U17="A",2,IF(U17="B",1,IF(U17="C",0))))) | BO17: =IF(B17="","",IF(COUNT(BK17:BN17)=0,"",ROUND(AVERAGE(BK17:BN17),0))) | BP17: =IF(X17="","",IF(X17="AD",3,IF(X17="A",2,IF(X17="B",1,IF(X17="C",0))))) | BQ17: =IF(Y17="","",IF(Y17="AD",3,IF(Y17="A",2,IF(Y17="B",1,IF(Y17="C",0))))) | BR17: =IF(Z17="","",IF(Z17="AD",3,IF(Z17="A",2,IF(Z17="B",1,IF(Z17="C",0))))) | BS17: =IF(AA17="","",IF(AA17="AD",3,IF(AA17="A",2,IF(AA17="B",1,IF(AA17="C",0))))) | BT17: =IF(B17="","",IF(COUNT(BP17:BS17)=0,"",ROUND(AVERAGE(BP17:BS17),0))) | BU17: =IF(ISERROR(AVERAGE(BD17,BJ17,BO17,BT17)),"",ROUND(AVERAGE(BD17,BJ17,BO17,BT17),0)) | BV17: =IF(AE17="","",IF(AE17="AD",3,IF(AE17="A",2,IF(AE17="B",1,IF(AE17="C",0))))) | BW17: =IF(AF17="","",IF(AF17="AD",3,IF(AF17="A",2,IF(AF17="B",1,IF(AF17="C",0))))) | BX17: =IF(AG17="","",IF(AG17="AD",3,IF(AG17="A",2,IF(AG17="B",1,IF(AG17="C",0))))) | BY17: =IF(AH17="","",IF(AH17="AD",3,IF(AH17="A",2,IF(AH17="B",1,IF(AH17="C",0))))) | BZ17: =IF(B17="","",IF(COUNT(BV17:BY17)=0,"",ROUND(AVERAGE(BV17:BY17),0))) | CA17: =IF(AJ17="","",IF(AJ17="AD",3,IF(AJ17="A",2,IF(AJ17="B",1,IF(AJ17="C",0))))) | CB17: =IF(AK17="","",IF(AK17="AD",3,IF(AK17="A",2,IF(AK17="B",1,IF(AK17="C",0))))) | CC17: =IF(AL17="","",IF(AL17="AD",3,IF(AL17="A",2,IF(AL17="B",1,IF(AL17="C",0))))) | CD17: =IF(B17="","",IF(COUNT(CA17:CC17)=0,"",ROUND(AVERAGE(CA17:CC17),0)))
A18: 9 | B18: ='Datos '!D16 -> 0 | I18: =IF(BD18="","",IF(BD18=3,"AD",IF(BD18=2, "A",IF(BD18= 1, "B",IF(BD18= 0, "C"))))) | P18: =IF(BJ18="","",IF(BJ18=3,"AD",IF(BJ18=2, "A",IF(BJ18= 1, "B",IF(BJ18= 0, "C"))))) | V18: =IF(BO18="","",IF(BO18=3,"AD",IF(BO18=2, "A",IF(BO18= 1, "B",IF(BO18= 0, "C"))))) | AB18: =IF(BT18="","",IF(BT18=3,"AD",IF(BT18=2, "A",IF(BT18= 1, "B",IF(BT18= 0, "C"))))) | AD18: =IF(BU18="","",IF(BU18=3,"AD",IF(BU18=2, "A",IF(BU18= 1, "B",IF(BU18= 0, "C"))))) | AI18: =IF(BZ18="","",IF(BZ18=3,"AD",IF(BZ18=2, "A",IF(BZ18= 1, "B",IF(BZ18= 0, "C"))))) | AM18: =IF(CD18="","",IF(CD18=3,"AD",IF(CD18=2, "A",IF(CD18= 1, "B",IF(CD18= 0, "C"))))) | AN18: =IF(AD18="","No presenta evidencias para su calificación",IF(AD18="AD","Demuestra aprendizaje que van más allá del nivel esperado",IF(AD18="A","Demuestra manejo satisfactorio en todas las tareas propuestas",IF(AD18="B","Está próximo al nivel esperado para lo cual requiere acompañamiento durante un tiempo razonable",IF(AD18= "C","No logro el desarrollo de las competencias",))))) -> No presenta evidencias para su calificación | AX18: =IF(C18="","",IF(C18="AD",3,IF(C18="A",2,IF(C18="B",1,IF(C18="C",0))))) | AY18: =IF(D18="","",IF(D18="AD",3,IF(D18="A",2,IF(D18="B",1,IF(D18="C",0))))) | AZ18: =IF(E18="","",IF(E18="AD",3,IF(E18="A",2,IF(E18="B",1,IF(E18="C",0))))) | BA18: =IF(F18="","",IF(F18="AD",3,IF(F18="A",2,IF(F18="B",1,IF(F18="C",0))))) | BB18: =IF(G18="","",IF(G18="AD",3,IF(G18="A",2,IF(G18="B",1,IF(G18="C",0))))) | BC18: =IF(H18="","",IF(H18="AD",3,IF(H18="A",2,IF(H18="B",1,IF(H18="C",0))))) | BD18: =IF(B18="","",IF(COUNT(AX18:BC18)=0,"",ROUND(AVERAGE(AX18:BC18),0))) | BE18: =IF(K18="","",IF(K18="AD",3,IF(K18="A",2,IF(K18="B",1,IF(K18="C",0))))) | BF18: =IF(L18="","",IF(L18="AD",3,IF(L18="A",2,IF(L18="B",1,IF(L18="C",0))))) | BG18: =IF(M18="","",IF(M18="AD",3,IF(M18="A",2,IF(M18="B",1,IF(M18="C",0))))) | BH18: =IF(N18="","",IF(N18="AD",3,IF(N18="A",2,IF(N18="B",1,IF(N18="C",0))))) | BI18: =IF(O18="","",IF(O18="AD",3,IF(O18="A",2,IF(O18="B",1,IF(O18="C",0))))) | BJ18: =IF(B18="","",IF(COUNT(BE18:BI18)=0,"",ROUND(AVERAGE(BE18:BI18),0))) | BK18: =IF(R18="","",IF(R18="AD",3,IF(R18="A",2,IF(R18="B",1,IF(R18="C",0))))) | BL18: =IF(S18="","",IF(S18="AD",3,IF(S18="A",2,IF(S18="B",1,IF(S18="C",0))))) | BM18: =IF(T18="","",IF(T18="AD",3,IF(T18="A",2,IF(T18="B",1,IF(T18="C",0))))) | BN18: =IF(U18="","",IF(U18="AD",3,IF(U18="A",2,IF(U18="B",1,IF(U18="C",0))))) | BO18: =IF(B18="","",IF(COUNT(BK18:BN18)=0,"",ROUND(AVERAGE(BK18:BN18),0))) | BP18: =IF(X18="","",IF(X18="AD",3,IF(X18="A",2,IF(X18="B",1,IF(X18="C",0))))) | BQ18: =IF(Y18="","",IF(Y18="AD",3,IF(Y18="A",2,IF(Y18="B",1,IF(Y18="C",0))))) | BR18: =IF(Z18="","",IF(Z18="AD",3,IF(Z18="A",2,IF(Z18="B",1,IF(Z18="C",0))))) | BS18: =IF(AA18="","",IF(AA18="AD",3,IF(AA18="A",2,IF(AA18="B",1,IF(AA18="C",0))))) | BT18: =IF(B18="","",IF(COUNT(BP18:BS18)=0,"",ROUND(AVERAGE(BP18:BS18),0))) | BU18: =IF(ISERROR(AVERAGE(BD18,BJ18,BO18,BT18)),"",ROUND(AVERAGE(BD18,BJ18,BO18,BT18),0)) | BV18: =IF(AE18="","",IF(AE18="AD",3,IF(AE18="A",2,IF(AE18="B",1,IF(AE18="C",0))))) | BW18: =IF(AF18="","",IF(AF18="AD",3,IF(AF18="A",2,IF(AF18="B",1,IF(AF18="C",0))))) | BX18: =IF(AG18="","",IF(AG18="AD",3,IF(AG18="A",2,IF(AG18="B",1,IF(AG18="C",0))))) | BY18: =IF(AH18="","",IF(AH18="AD",3,IF(AH18="A",2,IF(AH18="B",1,IF(AH18="C",0))))) | BZ18: =IF(B18="","",IF(COUNT(BV18:BY18)=0,"",ROUND(AVERAGE(BV18:BY18),0))) | CA18: =IF(AJ18="","",IF(AJ18="AD",3,IF(AJ18="A",2,IF(AJ18="B",1,IF(AJ18="C",0))))) | CB18: =IF(AK18="","",IF(AK18="AD",3,IF(AK18="A",2,IF(AK18="B",1,IF(AK18="C",0))))) | CC18: =IF(AL18="","",IF(AL18="AD",3,IF(AL18="A",2,IF(AL18="B",1,IF(AL18="C",0))))) | CD18: =IF(B18="","",IF(COUNT(CA18:CC18)=0,"",ROUND(AVERAGE(CA18:CC18),0)))
A19: 10 | B19: ='Datos '!D17 -> 0 | I19: =IF(BD19="","",IF(BD19=3,"AD",IF(BD19=2, "A",IF(BD19= 1, "B",IF(BD19= 0, "C"))))) | P19: =IF(BJ19="","",IF(BJ19=3,"AD",IF(BJ19=2, "A",IF(BJ19= 1, "B",IF(BJ19= 0, "C"))))) | V19: =IF(BO19="","",IF(BO19=3,"AD",IF(BO19=2, "A",IF(BO19= 1, "B",IF(BO19= 0, "C"))))) | AB19: =IF(BT19="","",IF(BT19=3,"AD",IF(BT19=2, "A",IF(BT19= 1, "B",IF(BT19= 0, "C"))))) | AD19: =IF(BU19="","",IF(BU19=3,"AD",IF(BU19=2, "A",IF(BU19= 1, "B",IF(BU19= 0, "C"))))) | AI19: =IF(BZ19="","",IF(BZ19=3,"AD",IF(BZ19=2, "A",IF(BZ19= 1, "B",IF(BZ19= 0, "C"))))) | AM19: =IF(CD19="","",IF(CD19=3,"AD",IF(CD19=2, "A",IF(CD19= 1, "B",IF(CD19= 0, "C"))))) | AN19: =IF(AD19="","No presenta evidencias para su calificación",IF(AD19="AD","Demuestra aprendizaje que van más allá del nivel esperado",IF(AD19="A","Demuestra manejo satisfactorio en todas las tareas propuestas",IF(AD19="B","Está próximo al nivel esperado para lo cual requiere acompañamiento durante un tiempo razonable",IF(AD19= "C","No logro el desarrollo de las competencias",))))) -> No presenta evidencias para su calificación | AX19: =IF(C19="","",IF(C19="AD",3,IF(C19="A",2,IF(C19="B",1,IF(C19="C",0))))) | AY19: =IF(D19="","",IF(D19="AD",3,IF(D19="A",2,IF(D19="B",1,IF(D19="C",0))))) | AZ19: =IF(E19="","",IF(E19="AD",3,IF(E19="A",2,IF(E19="B",1,IF(E19="C",0))))) | BA19: =IF(F19="","",IF(F19="AD",3,IF(F19="A",2,IF(F19="B",1,IF(F19="C",0))))) | BB19: =IF(G19="","",IF(G19="AD",3,IF(G19="A",2,IF(G19="B",1,IF(G19="C",0))))) | BC19: =IF(H19="","",IF(H19="AD",3,IF(H19="A",2,IF(H19="B",1,IF(H19="C",0))))) | BD19: =IF(B19="","",IF(COUNT(AX19:BC19)=0,"",ROUND(AVERAGE(AX19:BC19),0))) | BE19: =IF(K19="","",IF(K19="AD",3,IF(K19="A",2,IF(K19="B",1,IF(K19="C",0))))) | BF19: =IF(L19="","",IF(L19="AD",3,IF(L19="A",2,IF(L19="B",1,IF(L19="C",0))))) | BG19: =IF(M19="","",IF(M19="AD",3,IF(M19="A",2,IF(M19="B",1,IF(M19="C",0))))) | BH19: =IF(N19="","",IF(N19="AD",3,IF(N19="A",2,IF(N19="B",1,IF(N19="C",0))))) | BI19: =IF(O19="","",IF(O19="AD",3,IF(O19="A",2,IF(O19="B",1,IF(O19="C",0))))) | BJ19: =IF(B19="","",IF(COUNT(BE19:BI19)=0,"",ROUND(AVERAGE(BE19:BI19),0))) | BK19: =IF(R19="","",IF(R19="AD",3,IF(R19="A",2,IF(R19="B",1,IF(R19="C",0))))) | BL19: =IF(S19="","",IF(S19="AD",3,IF(S19="A",2,IF(S19="B",1,IF(S19="C",0))))) | BM19: =IF(T19="","",IF(T19="AD",3,IF(T19="A",2,IF(T19="B",1,IF(T19="C",0))))) | BN19: =IF(U19="","",IF(U19="AD",3,IF(U19="A",2,IF(U19="B",1,IF(U19="C",0))))) | BO19: =IF(B19="","",IF(COUNT(BK19:BN19)=0,"",ROUND(AVERAGE(BK19:BN19),0))) | BP19: =IF(X19="","",IF(X19="AD",3,IF(X19="A",2,IF(X19="B",1,IF(X19="C",0))))) | BQ19: =IF(Y19="","",IF(Y19="AD",3,IF(Y19="A",2,IF(Y19="B",1,IF(Y19="C",0))))) | BR19: =IF(Z19="","",IF(Z19="AD",3,IF(Z19="A",2,IF(Z19="B",1,IF(Z19="C",0))))) | BS19: =IF(AA19="","",IF(AA19="AD",3,IF(AA19="A",2,IF(AA19="B",1,IF(AA19="C",0))))) | BT19: =IF(B19="","",IF(COUNT(BP19:BS19)=0,"",ROUND(AVERAGE(BP19:BS19),0))) | BU19: =IF(ISERROR(AVERAGE(BD19,BJ19,BO19,BT19)),"",ROUND(AVERAGE(BD19,BJ19,BO19,BT19),0)) | BV19: =IF(AE19="","",IF(AE19="AD",3,IF(AE19="A",2,IF(AE19="B",1,IF(AE19="C",0))))) | BW19: =IF(AF19="","",IF(AF19="AD",3,IF(AF19="A",2,IF(AF19="B",1,IF(AF19="C",0))))) | BX19: =IF(AG19="","",IF(AG19="AD",3,IF(AG19="A",2,IF(AG19="B",1,IF(AG19="C",0))))) | BY19: =IF(AH19="","",IF(AH19="AD",3,IF(AH19="A",2,IF(AH19="B",1,IF(AH19="C",0))))) | BZ19: =IF(B19="","",IF(COUNT(BV19:BY19)=0,"",ROUND(AVERAGE(BV19:BY19),0))) | CA19: =IF(AJ19="","",IF(AJ19="AD",3,IF(AJ19="A",2,IF(AJ19="B",1,IF(AJ19="C",0))))) | CB19: =IF(AK19="","",IF(AK19="AD",3,IF(AK19="A",2,IF(AK19="B",1,IF(AK19="C",0))))) | CC19: =IF(AL19="","",IF(AL19="AD",3,IF(AL19="A",2,IF(AL19="B",1,IF(AL19="C",0))))) | CD19: =IF(B19="","",IF(COUNT(CA19:CC19)=0,"",ROUND(AVERAGE(CA19:CC19),0)))
